/home/luc/hgwork/lino/docs/api/lino.modlib.pages.fixtures.intro.rst:4: WARNING: autodoc: failed to import module u'lino.modlib.pages.fixtures.intro'; the following exception was raised:
Traceback (most recent call last):
  File "/home/luc/pythonenvs/py27/local/lib/python2.7/site-packages/sphinx/ext/autodoc.py", line 335, in import_object
    __import__(self.modname)
  File "/home/luc/hgwork/lino/lino/modlib/pages/fixtures/intro.py", line 50, in <module>
    """)
  File "/home/luc/hgwork/lino/lino/modlib/pages/builder.py", line 40, in page
    obj = pages.lookup(ref, None)
  File "/home/luc/hgwork/lino/lino/modlib/pages/models.py", line 235, in lookup
    return Page.get_by_ref(ref, *args, **kw)
  File "/home/luc/hgwork/lino/lino/mixins/__init__.py", line 680, in get_by_ref
    return cls.objects.get(ref=ref)
  File "/home/luc/pythonenvs/py27/local/lib/python2.7/site-packages/django/db/models/manager.py", line 151, in get
    return self.get_queryset().get(*args, **kwargs)
  File "/home/luc/pythonenvs/py27/local/lib/python2.7/site-packages/django/db/models/query.py", line 301, in get
    num = len(clone)
  File "/home/luc/pythonenvs/py27/local/lib/python2.7/site-packages/django/db/models/query.py", line 77, in __len__
    self._fetch_all()
  File "/home/luc/pythonenvs/py27/local/lib/python2.7/site-packages/django/db/models/query.py", line 854, in _fetch_all
    self._result_cache = list(self.iterator())
  File "/home/luc/pythonenvs/py27/local/lib/python2.7/site-packages/django/db/models/query.py", line 220, in iterator
    for row in compiler.results_iter():
  File "/home/luc/pythonenvs/py27/local/lib/python2.7/site-packages/django/db/models/sql/compiler.py", line 710, in results_iter
    for rows in self.execute_sql(MULTI):
  File "/home/luc/pythonenvs/py27/local/lib/python2.7/site-packages/django/db/models/sql/compiler.py", line 781, in execute_sql
    cursor.execute(sql, params)
  File "/home/luc/pythonenvs/py27/local/lib/python2.7/site-packages/django/db/backends/util.py", line 69, in execute
    return super(CursorDebugWrapper, self).execute(sql, params)
  File "/home/luc/pythonenvs/py27/local/lib/python2.7/site-packages/django/db/backends/util.py", line 53, in execute
    return self.cursor.execute(sql, params)
  File "/home/luc/pythonenvs/py27/local/lib/python2.7/site-packages/django/db/utils.py", line 99, in __exit__
    six.reraise(dj_exc_type, dj_exc_value, traceback)
  File "/home/luc/pythonenvs/py27/local/lib/python2.7/site-packages/django/db/backends/util.py", line 53, in execute
    return self.cursor.execute(sql, params)
  File "/home/luc/pythonenvs/py27/local/lib/python2.7/site-packages/django/db/backends/sqlite3/base.py", line 450, in execute
    return Database.Cursor.execute(self, query, params)
OperationalError: no such column: pages_page.body_de
/home/luc/hgwork/lino/docs/api/lino.modlib.pages.fixtures.man.rst:4: WARNING: autodoc: failed to import module u'lino.modlib.pages.fixtures.man'; the following exception was raised:
Traceback (most recent call last):
  File "/home/luc/pythonenvs/py27/local/lib/python2.7/site-packages/sphinx/ext/autodoc.py", line 335, in import_object
    __import__(self.modname)
  File "/home/luc/hgwork/lino/lino/modlib/pages/fixtures/man.py", line 37, in <module>
    """)
  File "/home/luc/hgwork/lino/lino/modlib/pages/builder.py", line 40, in page
    obj = pages.lookup(ref, None)
  File "/home/luc/hgwork/lino/lino/modlib/pages/models.py", line 235, in lookup
    return Page.get_by_ref(ref, *args, **kw)
  File "/home/luc/hgwork/lino/lino/mixins/__init__.py", line 680, in get_by_ref
    return cls.objects.get(ref=ref)
  File "/home/luc/pythonenvs/py27/local/lib/python2.7/site-packages/django/db/models/manager.py", line 151, in get
    return self.get_queryset().get(*args, **kwargs)
  File "/home/luc/pythonenvs/py27/local/lib/python2.7/site-packages/django/db/models/query.py", line 301, in get
    num = len(clone)
  File "/home/luc/pythonenvs/py27/local/lib/python2.7/site-packages/django/db/models/query.py", line 77, in __len__
    self._fetch_all()
  File "/home/luc/pythonenvs/py27/local/lib/python2.7/site-packages/django/db/models/query.py", line 854, in _fetch_all
    self._result_cache = list(self.iterator())
  File "/home/luc/pythonenvs/py27/local/lib/python2.7/site-packages/django/db/models/query.py", line 220, in iterator
    for row in compiler.results_iter():
  File "/home/luc/pythonenvs/py27/local/lib/python2.7/site-packages/django/db/models/sql/compiler.py", line 710, in results_iter
    for rows in self.execute_sql(MULTI):
  File "/home/luc/pythonenvs/py27/local/lib/python2.7/site-packages/django/db/models/sql/compiler.py", line 781, in execute_sql
    cursor.execute(sql, params)
  File "/home/luc/pythonenvs/py27/local/lib/python2.7/site-packages/django/db/backends/util.py", line 69, in execute
    return super(CursorDebugWrapper, self).execute(sql, params)
  File "/home/luc/pythonenvs/py27/local/lib/python2.7/site-packages/django/db/backends/util.py", line 53, in execute
    return self.cursor.execute(sql, params)
  File "/home/luc/pythonenvs/py27/local/lib/python2.7/site-packages/django/db/utils.py", line 99, in __exit__
    six.reraise(dj_exc_type, dj_exc_value, traceback)
  File "/home/luc/pythonenvs/py27/local/lib/python2.7/site-packages/django/db/backends/util.py", line 53, in execute
    return self.cursor.execute(sql, params)
  File "/home/luc/pythonenvs/py27/local/lib/python2.7/site-packages/django/db/backends/sqlite3/base.py", line 450, in execute
    return Database.Cursor.execute(self, query, params)
OperationalError: no such column: pages_page.body_de
/home/luc/hgwork/lino/docs/api/lino.modlib.extjs.rst:12: WARNING: unknown document: /about/proprietary
WARNING: logo file 'logo.png' does not exist ('/home/luc/hgwork/lino/docs')
