/home/luc/hgwork/lino/docs/api/lino.projects.homeworkschool.settings.demo.rst:4: WARNING: autodoc: failed to import module u'lino.projects.homeworkschool.settings.demo'; the following exception was raised:
Traceback (most recent call last):
  File "/home/luc/repositories/sphinx/sphinx/ext/autodoc.py", line 367, in import_object
    __import__(self.modname)
  File "/home/luc/hgwork/lino/lino/projects/homeworkschool/settings/demo.py", line 2, in <module>
    SITE = Site(globals(), title=Site.verbose_name + " demo")
  File "/home/luc/hgwork/lino/lino/ad.py", line 449, in __init__
    super(Site, self). __init__(*args, **kwargs)
  File "/home/luc/hgwork/site/djangosite/djangosite_site.py", line 171, in __init__
    self.load_plugins()
  File "/home/luc/hgwork/site/djangosite/djangosite_site.py", line 316, in load_plugins
    raise Exception("20140825")
Exception: 20140825
/home/luc/hgwork/lino/docs/api/lino.projects.min2.modlib.contacts.models.rst:4: WARNING: autodoc: failed to import module u'lino.projects.min2.modlib.contacts.models'; the following exception was raised:
Traceback (most recent call last):
  File "/home/luc/repositories/sphinx/sphinx/ext/autodoc.py", line 367, in import_object
    __import__(self.modname)
  File "/home/luc/hgwork/lino/lino/projects/min2/modlib/contacts/models.py", line 33, in <module>
    class Partner(Partner, addresses.AddressOwner, mixins.CreatedModified):
  File "/home/luc/pythonenvs/py27/local/lib/python2.7/site-packages/django/db/models/base.py", line 96, in __new__
    new_class.add_to_class('_meta', Options(meta, **kwargs))
  File "/home/luc/pythonenvs/py27/local/lib/python2.7/site-packages/django/db/models/base.py", line 264, in add_to_class
    value.contribute_to_class(cls, name)
  File "/home/luc/pythonenvs/py27/local/lib/python2.7/site-packages/django/db/models/options.py", line 114, in contribute_to_class
    raise Exception("20140516 %r" % self.verbose_name)
Exception: 20140516 u'partner'
/home/luc/hgwork/lino/docs/api/lino.projects.presto.modlib.contacts.models.rst:4: WARNING: autodoc: failed to import module u'lino.projects.presto.modlib.contacts.models'; the following exception was raised:
Traceback (most recent call last):
  File "/home/luc/repositories/sphinx/sphinx/ext/autodoc.py", line 367, in import_object
    __import__(self.modname)
  File "/home/luc/hgwork/lino/lino/projects/presto/modlib/contacts/models.py", line 90, in <module>
    class Person(Partner, Person):
  File "/home/luc/pythonenvs/py27/local/lib/python2.7/site-packages/django/db/models/base.py", line 79, in __new__
    new_class = super_new(cls, name, bases, {'__module__': module})
TypeError: Error when calling the metaclass bases
    Cannot create a consistent method resolution
order (MRO) for bases Partner, Person
