/home/luc/hgwork/lino/docs/api/lino.modlib.humanlinks.models.rst:4: WARNING: autodoc: failed to import module u'lino.modlib.humanlinks.models'; the following exception was raised:
Traceback (most recent call last):
  File "/home/luc/repositories/sphinx/sphinx/ext/autodoc.py", line 367, in import_object
    __import__(self.modname)
  File "/home/luc/hgwork/lino/lino/modlib/humanlinks/models.py", line 105, in <module>
    class Link(dd.Model):
  File "/home/luc/hgwork/lino/lino/modlib/humanlinks/models.py", line 113, in Link
    dd.apps.humanlinks.human_model,
  File "/home/luc/hgwork/atelier/atelier/utils.py", line 50, in __getattr__
    name, ', '.join(self.keys())))
AttributeError: AttrDict instance has no key 'humanlinks' (keys are addresses, sepa, sales, ledger, attestations, accounts, djangosite, contacts, system, extjs, households, contenttypes, postings, vat, uploads, north, users, sessions, pages, concepts, lino, iban, outbox, properties, about, countries, plain, notes, courses, products, extensible, cal, changes)
WARNING: logo file 'logo.png' does not exist
WARNING: favicon file 'favicon.ico' does not exist
